Workbook

Sheet Data
A1: Id | B1: MSSubClass | C1: MSZoning | D1: LotFrontage | E1: LotArea | F1: Street | G1: Alley | H1: LotShape | I1: LandContour | J1: Utilities | K1: LotConfig | L1: LandSlope | M1: Neighborhood | N1: Condition1 | O1: Condition2 | P1: BldgType | Q1: HouseStyle | R1: OverallQual | S1: OverallCond | T1: YearBuilt | U1: YearRemodAdd | V1: RoofStyle | W1: RoofMatl | X1: Exterior1st | Y1: Exterior2nd | Z1: MasVnrType | AA1: MasVnrArea | AB1: ExterQual | AC1: ExterCond | AD1: Foundation | AE1: BsmtQual | AF1: BsmtCond | AG1: BsmtExposure | AH1: BsmtFinType1 | AI1: BsmtFinSF1 | AJ1: BsmtFinType2 | AK1: BsmtFinSF2 | AL1: BsmtUnfSF | AM1: TotalBsmtSF | AN1: Heating | AO1: HeatingQC | AP1: CentralAir | AQ1: Electrical | AR1: 1stFlrSF | AS1: 2ndFlrSF | AT1: LowQualFinSF | AU1: GrLivArea | AV1: BsmtFullBath | AW1: BsmtHalfBath | AX1: FullBath | AY1: HalfBath | AZ1: BedroomAbvGr | BA1: KitchebvGr | BB1: KitchenQual | BC1: TotRmsAbvGrd | BD1: Functiol | BE1: Fireplaces | BF1: FireplaceQu | BG1: GarageType | BH1: GarageYrBlt | BI1: GarageFinish | BJ1: GarageCars | BK1: GarageArea | BL1: GarageQual | BM1: GarageCond | BN1: PavedDrive | BO1: WoodDeckSF | BP1: OpenPorchSF | BQ1: EnclosedPorch | BR1: 3SsnPorch | BS1: ScreenPorch | BT1: PoolArea | BU1: PoolQC | BV1: Fence | BW1: MiscFeature | BX1: MiscVal | BY1: MoSold | BZ1: YrSold | CA1: SaleType | CB1: SaleCondition | CC1: SalePrice
A2: 1 | B2: 60 | C2: RL | D2: 65 | E2: 8450 | F2: Pave | H2: Reg | I2: Lvl | J2: AllPub | K2: Inside | L2: Gtl | M2: CollgCr | N2: Norm | O2: Norm | P2: 1Fam | Q2: 2Story | R2: 7 | S2: 5 | T2: 2003 | U2: 2003 | V2: Gable | W2: CompShg | X2: VinylSd | Y2: VinylSd | Z2: BrkFace | AA2: 196 | AB2: Gd | AC2: TA | AD2: PConc | AE2: Gd | AF2: TA | AG2: No | AH2: GLQ | AI2: 706 | AJ2: Unf | AK2: 0 | AL2: 150 | AM2: 856 | AN2: GasA | AO2: Ex | AP2: Y | AQ2: SBrkr | AR2: 856 | AS2: 854 | AT2: 0 | AU2: 1710 | AV2: 1 | AW2: 0 | AX2: 2 | AY2: 1 | AZ2: 3 | BA2: 1 | BB2: Gd | BC2: 8 | BD2: Typ | BE2: 0 | BG2: Attchd | BH2: 2003 | BI2: RFn | BJ2: 2 | BK2: 548 | BL2: TA | BM2: TA | BN2: Y | BO2: 0 | BP2: 61 | BQ2: 0 | BR2: 0 | BS2: 0 | BT2: 0 | BX2: 0 | BY2: 2 | BZ2: 2008 | CA2: WD | CB2: Normal | CC2: 208500
A3: 2 | B3: 20 | C3: RL | D3: 80 | E3: 9600 | F3: Pave | H3: Reg | I3: Lvl | J3: AllPub | K3: FR2 | L3: Gtl | M3: Veenker | N3: Feedr | O3: Norm | P3: 1Fam | Q3: 1Story | R3: 6 | S3: 8 | T3: 1976 | U3: 1976 | V3: Gable | W3: CompShg | X3: MetalSd | Y3: MetalSd | Z3: None | AA3: 0 | AB3: TA | AC3: TA | AD3: CBlock | AE3: Gd | AF3: TA | AG3: Gd | AH3: ALQ | AI3: 978 | AJ3: Unf | AK3: 0 | AL3: 284 | AM3: 1262 | AN3: GasA | AO3: Ex | AP3: Y | AQ3: SBrkr | AR3: 1262 | AS3: 0 | AT3: 0 | AU3: 1262 | AV3: 0 | AW3: 1 | AX3: 2 | AY3: 0 | AZ3: 3 | BA3: 1 | BB3: TA | BC3: 6 | BD3: Typ | BE3: 1 | BF3: TA | BG3: Attchd | BH3: 1976 | BI3: RFn | BJ3: 2 | BK3: 460 | BL3: TA | BM3: TA | BN3: Y | BO3: 298 | BP3: 0 | BQ3: 0 | BR3: 0 | BS3: 0 | BT3: 0 | BX3: 0 | BY3: 5 | BZ3: 2007 | CA3: WD | CB3: Normal | CC3: 181500
A4: 3 | B4: 60 | C4: RL | D4: 68 | E4: 11250 | F4: Pave | H4: IR1 | I4: Lvl | J4: AllPub | K4: Inside | L4: Gtl | M4: CollgCr | N4: Norm | O4: Norm | P4: 1Fam | Q4: 2Story | R4: 7 | S4: 5 | T4: 2001 | U4: 2002 | V4: Gable | W4: CompShg | X4: VinylSd | Y4: VinylSd | Z4: BrkFace | AA4: 162 | AB4: Gd | AC4: TA | AD4: PConc | AE4: Gd | AF4: TA | AG4: Mn | AH4: GLQ | AI4: 486 | AJ4: Unf | AK4: 0 | AL4: 434 | AM4: 920 | AN4: GasA | AO4: Ex | AP4: Y | AQ4: SBrkr | AR4: 920 | AS4: 866 | AT4: 0 | AU4: 1786 | AV4: 1 | AW4: 0 | AX4: 2 | AY4: 1 | AZ4: 3 | BA4: 1 | BB4: Gd | BC4: 6 | BD4: Typ | BE4: 1 | BF4: TA | BG4: Attchd | BH4: 2001 | BI4: RFn | BJ4: 2 | BK4: 608 | BL4: TA | BM4: TA | BN4: Y | BO4: 0 | BP4: 42 | BQ4: 0 | BR4: 0 | BS4: 0 | BT4: 0 | BX4: 0 | BY4: 9 | BZ4: 2008 | CA4: WD | CB4: Normal | CC4: 223500
A5: 4 | B5: 70 | C5: RL | D5: 60 | E5: 9550 | F5: Pave | H5: IR1 | I5: Lvl | J5: AllPub | K5: Corner | L5: Gtl | M5: Crawfor | N5: Norm | O5: Norm | P5: 1Fam | Q5: 2Story | R5: 7 | S5: 5 | T5: 1915 | U5: 1970 | V5: Gable | W5: CompShg | X5: Wd Sdng | Y5: Wd Shng | Z5: None | AA5: 0 | AB5: TA | AC5: TA | AD5: BrkTil | AE5: TA | AF5: Gd | AG5: No | AH5: ALQ | AI5: 216 | AJ5: Unf | AK5: 0 | AL5: 540 | AM5: 756 | AN5: GasA | AO5: Gd | AP5: Y | AQ5: SBrkr | AR5: 961 | AS5: 756 | AT5: 0 | AU5: 1717 | AV5: 1 | AW5: 0 | AX5: 1 | AY5: 0 | AZ5: 3 | BA5: 1 | BB5: Gd | BC5: 7 | BD5: Typ | BE5: 1 | BF5: Gd | BG5: Detchd | BH5: 1998 | BI5: Unf | BJ5: 3 | BK5: 642 | BL5: TA | BM5: TA | BN5: Y | BO5: 0 | BP5: 35 | BQ5: 272 | BR5: 0 | BS5: 0 | BT5: 0 | BX5: 0 | BY5: 2 | BZ5: 2006 | CA5: WD | CB5: Abnorml | CC5: 140000
A6: 5 | B6: 60 | C6: RL | D6: 84 | E6: 14260 | F6: Pave | H6: IR1 | I6: Lvl | J6: AllPub | K6: FR2 | L6: Gtl | M6: NoRidge | N6: Norm | O6: Norm | P6: 1Fam | Q6: 2Story | R6: 8 | S6: 5 | T6: 2000 | U6: 2000 | V6: Gable | W6: CompShg | X6: VinylSd | Y6: VinylSd | Z6: BrkFace | AA6: 350 | AB6: Gd | AC6: TA | AD6: PConc | AE6: Gd | AF6: TA | AG6: Av | AH6: GLQ | AI6: 655 | AJ6: Unf | AK6: 0 | AL6: 490 | AM6: 1145 | AN6: GasA | AO6: Ex | AP6: Y | AQ6: SBrkr | AR6: 1145 | AS6: 1053 | AT6: 0 | AU6: 2198 | AV6: 1 | AW6: 0 | AX6: 2 | AY6: 1 | AZ6: 4 | BA6: 1 | BB6: Gd | BC6: 9 | BD6: Typ | BE6: 1 | BF6: TA | BG6: Attchd | BH6: 2000 | BI6: RFn | BJ6: 3 | BK6: 836 | BL6: TA | BM6: TA | BN6: Y | BO6: 192 | BP6: 84 | BQ6: 0 | BR6: 0 | BS6: 0 | BT6: 0 | BX6: 0 | BY6: 12 | BZ6: 2008 | CA6: WD | CB6: Normal | CC6: 250000
A7: 6 | B7: 50 | C7: RL | D7: 85 | E7: 14115 | F7: Pave | H7: IR1 | I7: Lvl | J7: AllPub | K7: Inside | L7: Gtl | M7: Mitchel | N7: Norm | O7: Norm | P7: 1Fam | Q7: 1.5Fin | R7: 5 | S7: 5 | T7: 1993 | U7: 1995 | V7: Gable | W7: CompShg | X7: VinylSd | Y7: VinylSd | Z7: None | AA7: 0 | AB7: TA | AC7: TA | AD7: Wood | AE7: Gd | AF7: TA | AG7: No | AH7: GLQ | AI7: 732 | AJ7: Unf | AK7: 0 | AL7: 64 | AM7: 796 | AN7: GasA | AO7: Ex | AP7: Y | AQ7: SBrkr | AR7: 796 | AS7: 566 | AT7: 0 | AU7: 1362 | AV7: 1 | AW7: 0 | AX7: 1 | AY7: 1 | AZ7: 1 | BA7: 1 | BB7: TA | BC7: 5 | BD7: Typ | BE7: 0 | BG7: Attchd | BH7: 1993 | BI7: Unf | BJ7: 2 | BK7: 480 | BL7: TA | BM7: TA | BN7: Y | BO7: 40 | BP7: 30 | BQ7: 0 | BR7: 320 | BS7: 0 | BT7: 0 | BV7: MnPrv | BW7: Shed | BX7: 700 | BY7: 10 | BZ7: 2009 | CA7: WD | CB7: Normal | CC7: 143000
A8: 7 | B8: 20 | C8: RL | D8: 75 | E8: 10084 | F8: Pave | H8: Reg | I8: Lvl | J8: AllPub | K8: Inside | L8: Gtl | M8: Somerst | N8: Norm | O8: Norm | P8: 1Fam | Q8: 1Story | R8: 8 | S8: 5 | T8: 2004 | U8: 2005 | V8: Gable | W8: CompShg | X8: VinylSd | Y8: VinylSd | Z8: Stone | AA8: 186 | AB8: Gd | AC8: TA | AD8: PConc | AE8: Ex | AF8: TA | AG8: Av | AH8: GLQ | AI8: 1369 | AJ8: Unf | AK8: 0 | AL8: 317 | AM8: 1686 | AN8: GasA | AO8: Ex | AP8: Y | AQ8: SBrkr | AR8: 1694 | AS8: 0 | AT8: 0 | AU8: 1694 | AV8: 1 | AW8: 0 | AX8: 2 | AY8: 0 | AZ8: 3 | BA8: 1 | BB8: Gd | BC8: 7 | BD8: Typ | BE8: 1 | BF8: Gd | BG8: Attchd | BH8: 2004 | BI8: RFn | BJ8: 2 | BK8: 636 | BL8: TA | BM8: TA | BN8: Y | BO8: 255 | BP8: 57 | BQ8: 0 | BR8: 0 | BS8: 0 | BT8: 0 | BX8: 0 | BY8: 8 | BZ8: 2007 | CA8: WD | CB8: Normal | CC8: 307000
A9: 8 | B9: 60 | C9: RL | E9: 10382 | F9: Pave | H9: IR1 | I9: Lvl | J9: AllPub | K9: Corner | L9: Gtl | M9: NWAmes | N9: PosN | O9: Norm | P9: 1Fam | Q9: 2Story | R9: 7 | S9: 6 | T9: 1973 | U9: 1973 | V9: Gable | W9: CompShg | X9: HdBoard | Y9: HdBoard | Z9: Stone | AA9: 240 | AB9: TA | AC9: TA | AD9: CBlock | AE9: Gd | AF9: TA | AG9: Mn | AH9: ALQ | AI9: 859 | AJ9: BLQ | AK9: 32 | AL9: 216 | AM9: 1107 | AN9: GasA | AO9: Ex | AP9: Y | AQ9: SBrkr | AR9: 1107 | AS9: 983 | AT9: 0 | AU9: 2090 | AV9: 1 | AW9: 0 | AX9: 2 | AY9: 1 | AZ9: 3 | BA9: 1 | BB9: TA | BC9: 7 | BD9: Typ | BE9: 2 | BF9: TA | BG9: Attchd | BH9: 1973 | BI9: RFn | BJ9: 2 | BK9: 484 | BL9: TA | BM9: TA | BN9: Y | BO9: 235 | BP9: 204 | BQ9: 228 | BR9: 0 | BS9: 0 | BT9: 0 | BW9: Shed | BX9: 350 | BY9: 11 | BZ9: 2009 | CA9: WD | CB9: Normal | CC9: 200000
A10: 9 | B10: 50 | C10: RM | D10: 51 | E10: 6120 | F10: Pave | H10: Reg | I10: Lvl | J10: AllPub | K10: Inside | L10: Gtl | M10: OldTown | N10: Artery | O10: Norm | P10: 1Fam | Q10: 1.5Fin | R10: 7 | S10: 5 | T10: 1931 | U10: 1950 | V10: Gable | W10: CompShg | X10: BrkFace | Y10: Wd Shng | Z10: None | AA10: 0 | AB10: TA | AC10: TA | AD10: BrkTil | AE10: TA | AF10: TA | AG10: No | AH10: Unf | AI10: 0 | AJ10: Unf | AK10: 0 | AL10: 952 | AM10: 952 | AN10: GasA | AO10: Gd | AP10: Y | AQ10: FuseF | AR10: 1022 | AS10: 752 | AT10: 0 | AU10: 1774 | AV10: 0 | AW10: 0 | AX10: 2 | AY10: 0 | AZ10: 2 | BA10: 2 | BB10: TA | BC10: 8 | BD10: Min1 | BE10: 2 | BF10: TA | BG10: Detchd | BH10: 1931 | BI10: Unf | BJ10: 2 | BK10: 468 | BL10: Fa | BM10: TA | BN10: Y | BO10: 90 | BP10: 0 | BQ10: 205 | BR10: 0 | BS10: 0 | BT10: 0 | BX10: 0 | BY10: 4 | BZ10: 2008 | CA10: WD | CB10: Abnorml | CC10: 129900
A11: 10 | B11: 190 | C11: RL | D11: 50 | E11: 7420 | F11: Pave | H11: Reg | I11: Lvl | J11: AllPub | K11: Corner | L11: Gtl | M11: BrkSide | N11: Artery | O11: Artery | P11: 2fmCon | Q11: 1.5Unf | R11: 5 | S11: 6 | T11: 1939 | U11: 1950 | V11: Gable | W11: CompShg | X11: MetalSd | Y11: MetalSd | Z11: None | AA11: 0 | AB11: TA | AC11: TA | AD11: BrkTil | AE11: TA | AF11: TA | AG11: No | AH11: GLQ | AI11: 851 | AJ11: Unf | AK11: 0 | AL11: 140 | AM11: 991 | AN11: GasA | AO11: Ex | AP11: Y | AQ11: SBrkr | AR11: 1077 | AS11: 0 | AT11: 0 | AU11: 1077 | AV11: 1 | AW11: 0 | AX11: 1 | AY11: 0 | AZ11: 2 | BA11: 2 | BB11: TA | BC11: 5 | BD11: Typ | BE11: 2 | BF11: TA | BG11: Attchd | BH11: 1939 | BI11: RFn | BJ11: 1 | BK11: 205 | BL11: Gd | BM11: TA | BN11: Y | BO11: 0 | BP11: 4 | BQ11: 0 | BR11: 0 | BS11: 0 | BT11: 0 | BX11: 0 | BY11: 1 | BZ11: 2008 | CA11: WD | CB11: Normal | CC11: 118000
A12: 11 | B12: 20 | C12: RL | D12: 70 | E12: 11200 | F12: Pave | H12: Reg | I12: Lvl | J12: AllPub | K12: Inside | L12: Gtl | M12: Sawyer | N12: Norm | O12: Norm | P12: 1Fam | Q12: 1Story | R12: 5 | S12: 5 | T12: 1965 | U12: 1965 | V12: Hip | W12: CompShg | X12: HdBoard | Y12: HdBoard | Z12: None | AA12: 0 | AB12: TA | AC12: TA | AD12: CBlock | AE12: TA | AF12: TA | AG12: No | AH12: Rec | AI12: 906 | AJ12: Unf | AK12: 0 | AL12: 134 | AM12: 1040 | AN12: GasA | AO12: Ex | AP12: Y | AQ12: SBrkr | AR12: 1040 | AS12: 0 | AT12: 0 | AU12: 1040 | AV12: 1 | AW12: 0 | AX12: 1 | AY12: 0 | AZ12: 3 | BA12: 1 | BB12: TA | BC12: 5 | BD12: Typ | BE12: 0 | BG12: Detchd | BH12: 1965 | BI12: Unf | BJ12: 1 | BK12: 384 | BL12: TA | BM12: TA | BN12: Y | BO12: 0 | BP12: 0 | BQ12: 0 | BR12: 0 | BS12: 0 | BT12: 0 | BX12: 0 | BY12: 2 | BZ12: 2008 | CA12: WD | CB12: Normal | CC12: 129500
A13: 12 | B13: 60 | C13: RL | D13: 85 | E13: 11924 | F13: Pave | H13: IR1 | I13: Lvl | J13: AllPub | K13: Inside | L13: Gtl | M13: NridgHt | N13: Norm | O13: Norm | P13: 1Fam | Q13: 2Story | R13: 9 | S13: 5 | T13: 2005 | U13: 2006 | V13: Hip | W13: CompShg | X13: WdShing | Y13: Wd Shng | Z13: Stone | AA13: 286 | AB13: Ex | AC13: TA | AD13: PConc | AE13: Ex | AF13: TA | AG13: No | AH13: GLQ | AI13: 998 | AJ13: Unf | AK13: 0 | AL13: 177 | AM13: 1175 | AN13: GasA | AO13: Ex | AP13: Y | AQ13: SBrkr | AR13: 1182 | AS13: 1142 | AT13: 0 | AU13: 2324 | AV13: 1 | AW13: 0 | AX13: 3 | AY13: 0 | AZ13: 4 | BA13: 1 | BB13: Ex | BC13: 11 | BD13: Typ | BE13: 2 | BF13: Gd | BG13: BuiltIn | BH13: 2005 | BI13: Fin | BJ13: 3 | BK13: 736 | BL13: TA | BM13: TA | BN13: Y | BO13: 147 | BP13: 21 | BQ13: 0 | BR13: 0 | BS13: 0 | BT13: 0 | BX13: 0 | BY13: 7 | BZ13: 2006 | CA13: New | CB13: Partial | CC13: 345000
A14: 13 | B14: 20 | C14: RL | E14: 12968 | F14: Pave | H14: IR2 | I14: Lvl | J14: AllPub | K14: Inside | L14: Gtl | M14: Sawyer | N14: Norm | O14: Norm | P14: 1Fam | Q14: 1Story | R14: 5 | S14: 6 | T14: 1962 | U14: 1962 | V14: Hip | W14: CompShg | X14: HdBoard | Y14: Plywood | Z14: None | AA14: 0 | AB14: TA | AC14: TA | AD14: CBlock | AE14: TA | AF14: TA | AG14: No | AH14: ALQ | AI14: 737 | AJ14: Unf | AK14: 0 | AL14: 175 | AM14: 912 | AN14: GasA | AO14: TA | AP14: Y | AQ14: SBrkr | AR14: 912 | AS14: 0 | AT14: 0 | AU14: 912 | AV14: 1 | AW14: 0 | AX14: 1 | AY14: 0 | AZ14: 2 | BA14: 1 | BB14: TA | BC14: 4 | BD14: Typ | BE14: 0 | BG14: Detchd | BH14: 1962 | BI14: Unf | BJ14: 1 | BK14: 352 | BL14: TA | BM14: TA | BN14: Y | BO14: 140 | BP14: 0 | BQ14: 0 | BR14: 0 | BS14: 176 | BT14: 0 | BX14: 0 | BY14: 9 | BZ14: 2008 | CA14: WD | CB14: Normal | CC14: 144000
A15: 14 | B15: 20 | C15: RL | D15: 91 | E15: 10652 | F15: Pave | H15: IR1 | I15: Lvl | J15: AllPub | K15: Inside | L15: Gtl | M15: CollgCr | N15: Norm | O15: Norm | P15: 1Fam | Q15: 1Story | R15: 7 | S15: 5 | T15: 2006 | U15: 2007 | V15: Gable | W15: CompShg | X15: VinylSd | Y15: VinylSd | Z15: Stone | AA15: 306 | AB15: Gd | AC15: TA | AD15: PConc | AE15: Gd | AF15: TA | AG15: Av | AH15: Unf | AI15: 0 | AJ15: Unf | AK15: 0 | AL15: 1494 | AM15: 1494 | AN15: GasA | AO15: Ex | AP15: Y | AQ15: SBrkr | AR15: 1494 | AS15: 0 | AT15: 0 | AU15: 1494 | AV15: 0 | AW15: 0 | AX15: 2 | AY15: 0 | AZ15: 3 | BA15: 1 | BB15: Gd | BC15: 7 | BD15: Typ | BE15: 1 | BF15: Gd | BG15: Attchd | BH15: 2006 | BI15: RFn | BJ15: 3 | BK15: 840 | BL15: TA | BM15: TA | BN15: Y | BO15: 160 | BP15: 33 | BQ15: 0 | BR15: 0 | BS15: 0 | BT15: 0 | BX15: 0 | BY15: 8 | BZ15: 2007 | CA15: New | CB15: Partial | CC15: 279500
A16: 15 | B16: 20 | C16: RL | E16: 10920 | F16: Pave | H16: IR1 | I16: Lvl | J16: AllPub | K16: Corner | L16: Gtl | M16: mes | N16: Norm | O16: Norm | P16: 1Fam | Q16: 1Story | R16: 6 | S16: 5 | T16: 1960 | U16: 1960 | V16: Hip | W16: CompShg | X16: MetalSd | Y16: MetalSd | Z16: BrkFace | AA16: 212 | AB16: TA | AC16: TA | AD16: CBlock | AE16: TA | AF16: TA | AG16: No | AH16: BLQ | AI16: 733 | AJ16: Unf | AK16: 0 | AL16: 520 | AM16: 1253 | AN16: GasA | AO16: TA | AP16: Y | AQ16: SBrkr | AR16: 1253 | AS16: 0 | AT16: 0 | AU16: 1253 | AV16: 1 | AW16: 0 | AX16: 1 | AY16: 1 | AZ16: 2 | BA16: 1 | BB16: TA | BC16: 5 | BD16: Typ | BE16: 1 | BF16: Fa | BG16: Attchd | BH16: 1960 | BI16: RFn | BJ16: 1 | BK16: 352 | BL16: TA | BM16: TA | BN16: Y | BO16: 0 | BP16: 213 | BQ16: 176 | BR16: 0 | BS16: 0 | BT16: 0 | BV16: GdWo | BX16: 0 | BY16: 5 | BZ16: 2008 | CA16: WD | CB16: Normal | CC16: 157000
A17: 16 | B17: 45 | C17: RM | D17: 51 | E17: 6120 | F17: Pave | H17: Reg | I17: Lvl | J17: AllPub | K17: Corner | L17: Gtl | M17: BrkSide | N17: Norm | O17: Norm | P17: 1Fam | Q17: 1.5Unf | R17: 7 | S17: 8 | T17: 1929 | U17: 2001 | V17: Gable | W17: CompShg | X17: Wd Sdng | Y17: Wd Sdng | Z17: None | AA17: 0 | AB17: TA | AC17: TA | AD17: BrkTil | AE17: TA | AF17: TA | AG17: No | AH17: Unf | AI17: 0 | AJ17: Unf | AK17: 0 | AL17: 832 | AM17: 832 | AN17: GasA | AO17: Ex | AP17: Y | AQ17: FuseA | AR17: 854 | AS17: 0 | AT17: 0 | AU17: 854 | AV17: 0 | AW17: 0 | AX17: 1 | AY17: 0 | AZ17: 2 | BA17: 1 | BB17: TA | BC17: 5 | BD17: Typ | BE17: 0 | BG17: Detchd | BH17: 1991 | BI17: Unf | BJ17: 2 | BK17: 576 | BL17: TA | BM17: TA | BN17: Y | BO17: 48 | BP17: 112 | BQ17: 0 | BR17: 0 | BS17: 0 | BT17: 0 | BV17: GdPrv | BX17: 0 | BY17: 7 | BZ17: 2007 | CA17: WD | CB17: Normal | CC17: 132000
A18: 17 | B18: 20 | C18: RL | E18: 11241 | F18: Pave | H18: IR1 | I18: Lvl | J18: AllPub | K18: CulDSac | L18: Gtl | M18: mes | N18: Norm | O18: Norm | P18: 1Fam | Q18: 1Story | R18: 6 | S18: 7 | T18: 1970 | U18: 1970 | V18: Gable | W18: CompShg | X18: Wd Sdng | Y18: Wd Sdng | Z18: BrkFace | AA18: 180 | AB18: TA | AC18: TA | AD18: CBlock | AE18: TA | AF18: TA | AG18: No | AH18: ALQ | AI18: 578 | AJ18: Unf | AK18: 0 | AL18: 426 | AM18: 1004 | AN18: GasA | AO18: Ex | AP18: Y | AQ18: SBrkr | AR18: 1004 | AS18: 0 | AT18: 0 | AU18: 1004 | AV18: 1 | AW18: 0 | AX18: 1 | AY18: 0 | AZ18: 2 | BA18: 1 | BB18: TA | BC18: 5 | BD18: Typ | BE18: 1 | BF18: TA | BG18: Attchd | BH18: 1970 | BI18: Fin | BJ18: 2 | BK18: 480 | BL18: TA | BM18: TA | BN18: Y | BO18: 0 | BP18: 0 | BQ18: 0 | BR18: 0 | BS18: 0 | BT18: 0 | BW18: Shed | BX18: 700 | BY18: 3 | BZ18: 2010 | CA18: WD | CB18: Normal | CC18: 149000
A19: 18 | B19: 90 | C19: RL | D19: 72 | E19: 10791 | F19: Pave | H19: Reg | I19: Lvl | J19: AllPub | K19: Inside | L19: Gtl | M19: Sawyer | N19: Norm | O19: Norm | P19: Duplex | Q19: 1Story | R19: 4 | S19: 5 | T19: 1967 | U19: 1967 | V19: Gable | W19: CompShg | X19: MetalSd | Y19: MetalSd | Z19: None | AA19: 0 | AB19: TA | AC19: TA | AD19: Slab | AI19: 0 | AK19: 0 | AL19: 0 | AM19: 0 | AN19: GasA | AO19: TA | AP19: Y | AQ19: SBrkr | AR19: 1296 | AS19: 0 | AT19: 0 | AU19: 1296 | AV19: 0 | AW19: 0 | AX19: 2 | AY19: 0 | AZ19: 2 | BA19: 2 | BB19: TA | BC19: 6 | BD19: Typ | BE19: 0 | BG19: CarPort | BH19: 1967 | BI19: Unf | BJ19: 2 | BK19: 516 | BL19: TA | BM19: TA | BN19: Y | BO19: 0 | BP19: 0 | BQ19: 0 | BR19: 0 | BS19: 0 | BT19: 0 | BW19: Shed | BX19: 500 | BY19: 10 | BZ19: 2006 | CA19: WD | CB19: Normal | CC19: 90000
A20: 19 | B20: 20 | C20: RL | D20: 66 | E20: 13695 | F20: Pave | H20: Reg | I20: Lvl | J20: AllPub | K20: Inside | L20: Gtl | M20: SawyerW | N20: RRAe | O20: Norm | P20: 1Fam | Q20: 1Story | R20: 5 | S20: 5 | T20: 2004 | U20: 2004 | V20: Gable | W20: CompShg | X20: VinylSd | Y20: VinylSd | Z20: None | AA20: 0 | AB20: TA | AC20: TA | AD20: PConc | AE20: TA | AF20: TA | AG20: No | AH20: GLQ | AI20: 646 | AJ20: Unf | AK20: 0 | AL20: 468 | AM20: 1114 | AN20: GasA | AO20: Ex | AP20: Y | AQ20: SBrkr | AR20: 1114 | AS20: 0 | AT20: 0 | AU20: 1114 | AV20: 1 | AW20: 0 | AX20: 1 | AY20: 1 | AZ20: 3 | BA20: 1 | BB20: Gd | BC20: 6 | BD20: Typ | BE20: 0 | BG20: Detchd | BH20: 2004 | BI20: Unf | BJ20: 2 | BK20: 576 | BL20: TA | BM20: TA | BN20: Y | BO20: 0 | BP20: 102 | BQ20: 0 | BR20: 0 | BS20: 0 | BT20: 0 | BX20: 0 | BY20: 6 | BZ20: 2008 | CA20: WD | CB20: Normal | CC20: 159000
A21: 20 | B21: 20 | C21: RL | D21: 70 | E21: 7560 | F21: Pave | H21: Reg | I21: Lvl | J21: AllPub | K21: Inside | L21: Gtl | M21: mes | N21: Norm | O21: Norm | P21: 1Fam | Q21: 1Story | R21: 5 | S21: 6 | T21: 1958 | U21: 1965 | V21: Hip | W21: CompShg | X21: BrkFace | Y21: Plywood | Z21: None | AA21: 0 | AB21: TA | AC21: TA | AD21: CBlock | AE21: TA | AF21: TA | AG21: No | AH21: LwQ | AI21: 504 | AJ21: Unf | AK21: 0 | AL21: 525 | AM21: 1029 | AN21: GasA | AO21: TA | AP21: Y | AQ21: SBrkr | AR21: 1339 | AS21: 0 | AT21: 0 | AU21: 1339 | AV21: 0 | AW21: 0 | AX21: 1 | AY21: 0 | AZ21: 3 | BA21: 1 | BB21: TA | BC21: 6 | BD21: Min1 | BE21: 0 | BG21: Attchd | BH21: 1958 | BI21: Unf | BJ21: 1 | BK21: 294 | BL21: TA | BM21: TA | BN21: Y | BO21: 0 | BP21: 0 | BQ21: 0 | BR21: 0 | BS21: 0 | BT21: 0 | BV21: MnPrv | BX21: 0 | BY21: 5 | BZ21: 2009 | CA21: COD | CB21: Abnorml | CC21: 139000
A22: 21 | B22: 60 | C22: RL | D22: 101 | E22: 14215 | F22: Pave | H22: IR1 | I22: Lvl | J22: AllPub | K22: Corner | L22: Gtl | M22: NridgHt | N22: Norm | O22: Norm | P22: 1Fam | Q22: 2Story | R22: 8 | S22: 5 | T22: 2005 | U22: 2006 | V22: Gable | W22: CompShg | X22: VinylSd | Y22: VinylSd | Z22: BrkFace | AA22: 380 | AB22: Gd | AC22: TA | AD22: PConc | AE22: Ex | AF22: TA | AG22: Av | AH22: Unf | AI22: 0 | AJ22: Unf | AK22: 0 | AL22: 1158 | AM22: 1158 | AN22: GasA | AO22: Ex | AP22: Y | AQ22: SBrkr | AR22: 1158 | AS22: 1218 | AT22: 0 | AU22: 2376 | AV22: 0 | AW22: 0 | AX22: 3 | AY22: 1 | AZ22: 4 | BA22: 1 | BB22: Gd | BC22: 9 | BD22: Typ | BE22: 1 | BF22: Gd | BG22: BuiltIn | BH22: 2005 | BI22: RFn | BJ22: 3 | BK22: 853 | BL22: TA | BM22: TA | BN22: Y | BO22: 240 | BP22: 154 | BQ22: 0 | BR22: 0 | BS22: 0 | BT22: 0 | BX22: 0 | BY22: 11 | BZ22: 2006 | CA22: New | CB22: Partial | CC22: 325300
A23: 22 | B23: 45 | C23: RM | D23: 57 | E23: 7449 | F23: Pave | G23: Grvl | H23: Reg | I23: Bnk | J23: AllPub | K23: Inside | L23: Gtl | M23: IDOTRR | N23: Norm | O23: Norm | P23: 1Fam | Q23: 1.5Unf | R23: 7 | S23: 7 | T23: 1930 | U23: 1950 | V23: Gable | W23: CompShg | X23: Wd Sdng | Y23: Wd Sdng | Z23: None | AA23: 0 | AB23: TA | AC23: TA | AD23: PConc | AE23: TA | AF23: TA | AG23: No | AH23: Unf | AI23: 0 | AJ23: Unf | AK23: 0 | AL23: 637 | AM23: 637 | AN23: GasA | AO23: Ex | AP23: Y | AQ23: FuseF | AR23: 1108 | AS23: 0 | AT23: 0 | AU23: 1108 | AV23: 0 | AW23: 0 | AX23: 1 | AY23: 0 | AZ23: 3 | BA23: 1 | BB23: Gd | BC23: 6 | BD23: Typ | BE23: 1 | BF23: Gd | BG23: Attchd | BH23: 1930 | BI23: Unf | BJ23: 1 | BK23: 280 | BL23: TA | BM23: TA | BN23: N | BO23: 0 | BP23: 0 | BQ23: 205 | BR23: 0 | BS23: 0 | BT23: 0 | BV23: GdPrv | BX23: 0 | BY23: 6 | BZ23: 2007 | CA23: WD | CB23: Normal | CC23: 139400
A24: 23 | B24: 20 | C24: RL | D24: 75 | E24: 9742 | F24: Pave | H24: Reg | I24: Lvl | J24: AllPub | K24: Inside | L24: Gtl | M24: CollgCr | N24: Norm | O24: Norm | P24: 1Fam | Q24: 1Story | R24: 8 | S24: 5 | T24: 2002 | U24: 2002 | V24: Hip | W24: CompShg | X24: VinylSd | Y24: VinylSd | Z24: BrkFace | AA24: 281 | AB24: Gd | AC24: TA | AD24: PConc | AE24: Gd | AF24: TA | AG24: No | AH24: Unf | AI24: 0 | AJ24: Unf | AK24: 0 | AL24: 1777 | AM24: 1777 | AN24: GasA | AO24: Ex | AP24: Y | AQ24: SBrkr | AR24: 1795 | AS24: 0 | AT24: 0 | AU24: 1795 | AV24: 0 | AW24: 0 | AX24: 2 | AY24: 0 | AZ24: 3 | BA24: 1 | BB24: Gd | BC24: 7 | BD24: Typ | BE24: 1 | BF24: Gd | BG24: Attchd | BH24: 2002 | BI24: RFn | BJ24: 2 | BK24: 534 | BL24: TA | BM24: TA | BN24: Y | BO24: 171 | BP24: 159 | BQ24: 0 | BR24: 0 | BS24: 0 | BT24: 0 | BX24: 0 | BY24: 9 | BZ24: 2008 | CA24: WD | CB24: Normal | CC24: 230000
A25: 24 | B25: 120 | C25: RM | D25: 44 | E25: 4224 | F25: Pave | H25: Reg | I25: Lvl | J25: AllPub | K25: Inside | L25: Gtl | M25: MeadowV | N25: Norm | O25: Norm | P25: TwnhsE | Q25: 1Story | R25: 5 | S25: 7 | T25: 1976 | U25: 1976 | V25: Gable | W25: CompShg | X25: CemntBd | Y25: CmentBd | Z25: None | AA25: 0 | AB25: TA | AC25: TA | AD25: PConc | AE25: Gd | AF25: TA | AG25: No | AH25: GLQ | AI25: 840 | AJ25: Unf | AK25: 0 | AL25: 200 | AM25: 1040 | AN25: GasA | AO25: TA | AP25: Y | AQ25: SBrkr | AR25: 1060 | AS25: 0 | AT25: 0 | AU25: 1060 | AV25: 1 | AW25: 0 | AX25: 1 | AY25: 0 | AZ25: 3 | BA25: 1 | BB25: TA | BC25: 6 | BD25: Typ | BE25: 1 | BF25: TA | BG25: Attchd | BH25: 1976 | BI25: Unf | BJ25: 2 | BK25: 572 | BL25: TA | BM25: TA | BN25: Y | BO25: 100 | BP25: 110 | BQ25: 0 | BR25: 0 | BS25: 0 | BT25: 0 | BX25: 0 | BY25: 6 | BZ25: 2007 | CA25: WD | CB25: Normal | CC25: 129900
A26: 25 | B26: 20 | C26: RL | E26: 8246 | F26: Pave | H26: IR1 | I26: Lvl | J26: AllPub | K26: Inside | L26: Gtl | M26: Sawyer | N26: Norm | O26: Norm | P26: 1Fam | Q26: 1Story | R26: 5 | S26: 8 | T26: 1968 | U26: 2001 | V26: Gable | W26: CompShg | X26: Plywood | Y26: Plywood | Z26: None | AA26: 0 | AB26: TA | AC26: Gd | AD26: CBlock | AE26: TA | AF26: TA | AG26: Mn | AH26: Rec | AI26: 188 | AJ26: ALQ | AK26: 668 | AL26: 204 | AM26: 1060 | AN26: GasA | AO26: Ex | AP26: Y | AQ26: SBrkr | AR26: 1060 | AS26: 0 | AT26: 0 | AU26: 1060 | AV26: 1 | AW26: 0 | AX26: 1 | AY26: 0 | AZ26: 3 | BA26: 1 | BB26: Gd | BC26: 6 | BD26: Typ | BE26: 1 | BF26: TA | BG26: Attchd | BH26: 1968 | BI26: Unf | BJ26: 1 | BK26: 270 | BL26: TA | BM26: TA | BN26: Y | BO26: 406 | BP26: 90 | BQ26: 0 | BR26: 0 | BS26: 0 | BT26: 0 | BV26: MnPrv | BX26: 0 | BY26: 5 | BZ26: 2010 | CA26: WD | CB26: Normal | CC26: 154000
A27: 26 | B27: 20 | C27: RL | D27: 110 | E27: 14230 | F27: Pave | H27: Reg | I27: Lvl | J27: AllPub | K27: Corner | L27: Gtl | M27: NridgHt | N27: Norm | O27: Norm | P27: 1Fam | Q27: 1Story | R27: 8 | S27: 5 | T27: 2007 | U27: 2007 | V27: Gable | W27: CompShg | X27: VinylSd | Y27: VinylSd | Z27: Stone | AA27: 640 | AB27: Gd | AC27: TA | AD27: PConc | AE27: Gd | AF27: TA | AG27: No | AH27: Unf | AI27: 0 | AJ27: Unf | AK27: 0 | AL27: 1566 | AM27: 1566 | AN27: GasA | AO27: Ex | AP27: Y | AQ27: SBrkr | AR27: 1600 | AS27: 0 | AT27: 0 | AU27: 1600 | AV27: 0 | AW27: 0 | AX27: 2 | AY27: 0 | AZ27: 3 | BA27: 1 | BB27: Gd | BC27: 7 | BD27: Typ | BE27: 1 | BF27: Gd | BG27: Attchd | BH27: 2007 | BI27: RFn | BJ27: 3 | BK27: 890 | BL27: TA | BM27: TA | BN27: Y | BO27: 0 | BP27: 56 | BQ27: 0 | BR27: 0 | BS27: 0 | BT27: 0 | BX27: 0 | BY27: 7 | BZ27: 2009 | CA27: WD | CB27: Normal | CC27: 256300
A28: 27 | B28: 20 | C28: RL | D28: 60 | E28: 7200 | F28: Pave | H28: Reg | I28: Lvl | J28: AllPub | K28: Corner | L28: Gtl | M28: mes | N28: Norm | O28: Norm | P28: 1Fam | Q28: 1Story | R28: 5 | S28: 7 | T28: 1951 | U28: 2000 | V28: Gable | W28: CompShg | X28: Wd Sdng | Y28: Wd Sdng | Z28: None | AA28: 0 | AB28: TA | AC28: TA | AD28: CBlock | AE28: TA | AF28: TA | AG28: Mn | AH28: BLQ | AI28: 234 | AJ28: Rec | AK28: 486 | AL28: 180 | AM28: 900 | AN28: GasA | AO28: TA | AP28: Y | AQ28: SBrkr | AR28: 900 | AS28: 0 | AT28: 0 | AU28: 900 | AV28: 0 | AW28: 1 | AX28: 1 | AY28: 0 | AZ28: 3 | BA28: 1 | BB28: Gd | BC28: 5 | BD28: Typ | BE28: 0 | BG28: Detchd | BH28: 2005 | BI28: Unf | BJ28: 2 | BK28: 576 | BL28: TA | BM28: TA | BN28: Y | BO28: 222 | BP28: 32 | BQ28: 0 | BR28: 0 | BS28: 0 | BT28: 0 | BX28: 0 | BY28: 5 | BZ28: 2010 | CA28: WD | CB28: Normal | CC28: 134800
A29: 28 | B29: 20 | C29: RL | D29: 98 | E29: 11478 | F29: Pave | H29: Reg | I29: Lvl | J29: AllPub | K29: Inside | L29: Gtl | M29: NridgHt | N29: Norm | O29: Norm | P29: 1Fam | Q29: 1Story | R29: 8 | S29: 5 | T29: 2007 | U29: 2008 | V29: Gable | W29: CompShg | X29: VinylSd | Y29: VinylSd | Z29: Stone | AA29: 200 | AB29: Gd | AC29: TA | AD29: PConc | AE29: Ex | AF29: TA | AG29: No | AH29: GLQ | AI29: 1218 | AJ29: Unf | AK29: 0 | AL29: 486 | AM29: 1704 | AN29: GasA | AO29: Ex | AP29: Y | AQ29: SBrkr | AR29: 1704 | AS29: 0 | AT29: 0 | AU29: 1704 | AV29: 1 | AW29: 0 | AX29: 2 | AY29: 0 | AZ29: 3 | BA29: 1 | BB29: Gd | BC29: 7 | BD29: Typ | BE29: 1 | BF29: Gd | BG29: Attchd | BH29: 2008 | BI29: RFn | BJ29: 3 | BK29: 772 | BL29: TA | BM29: TA | BN29: Y | BO29: 0 | BP29: 50 | BQ29: 0 | BR29: 0 | BS29: 0 | BT29: 0 | BX29: 0 | BY29: 5 | BZ29: 2010 | CA29: WD | CB29: Normal | CC29: 306000
A30: 29 | B30: 20 | C30: RL | D30: 47 | E30: 16321 | F30: Pave | H30: IR1 | I30: Lvl | J30: AllPub | K30: CulDSac | L30: Gtl | M30: mes | N30: Norm | O30: Norm | P30: 1Fam | Q30: 1Story | R30: 5 | S30: 6 | T30: 1957 | U30: 1997 | V30: Gable | W30: CompShg | X30: MetalSd | Y30: MetalSd | Z30: None | AA30: 0 | AB30: TA | AC30: TA | AD30: CBlock | AE30: TA | AF30: TA | AG30: Gd | AH30: BLQ | AI30: 1277 | AJ30: Unf | AK30: 0 | AL30: 207 | AM30: 1484 | AN30: GasA | AO30: TA | AP30: Y | AQ30: SBrkr | AR30: 1600 | AS30: 0 | AT30: 0 | AU30: 1600 | AV30: 1 | AW30: 0 | AX30: 1 | AY30: 0 | AZ30: 2 | BA30: 1 | BB30: TA | BC30: 6 | BD30: Typ | BE30: 2 | BF30: Gd | BG30: Attchd | BH30: 1957 | BI30: RFn | BJ30: 1 | BK30: 319 | BL30: TA | BM30: TA | BN30: Y | BO30: 288 | BP30: 258 | BQ30: 0 | BR30: 0 | BS30: 0 | BT30: 0 | BX30: 0 | BY30: 12 | BZ30: 2006 | CA30: WD | CB30: Normal | CC30: 207500
A31: 30 | B31: 30 | C31: RM | D31: 60 | E31: 6324 | F31: Pave | H31: IR1 | I31: Lvl | J31: AllPub | K31: Inside | L31: Gtl | M31: BrkSide | N31: Feedr | O31: RRNn | P31: 1Fam | Q31: 1Story | R31: 4 | S31: 6 | T31: 1927 | U31: 1950 | V31: Gable | W31: CompShg | X31: MetalSd | Y31: MetalSd | Z31: None | AA31: 0 | AB31: TA | AC31: TA | AD31: BrkTil | AE31: TA | AF31: TA | AG31: No | AH31: Unf | AI31: 0 | AJ31: Unf | AK31: 0 | AL31: 520 | AM31: 520 | AN31: GasA | AO31: Fa | AP31: N | AQ31: SBrkr | AR31: 520 | AS31: 0 | AT31: 0 | AU31: 520 | AV31: 0 | AW31: 0 | AX31: 1 | AY31: 0 | AZ31: 1 | BA31: 1 | BB31: Fa | BC31: 4 | BD31: Typ | BE31: 0 | BG31: Detchd | BH31: 1920 | BI31: Unf | BJ31: 1 | BK31: 240 | BL31: Fa | BM31: TA | BN31: Y | BO31: 49 | BP31: 0 | BQ31: 87 | BR31: 0 | BS31: 0 | BT31: 0 | BX31: 0 | BY31: 5 | BZ31: 2008 | CA31: WD | CB31: Normal | CC31: 68500
A32: 31 | B32: 70 | C32: C (all) | D32: 50 | E32: 8500 | F32: Pave | G32: Pave | H32: Reg | I32: Lvl | J32: AllPub | K32: Inside | L32: Gtl | M32: IDOTRR | N32: Feedr | O32: Norm | P32: 1Fam | Q32: 2Story | R32: 4 | S32: 4 | T32: 1920 | U32: 1950 | V32: Gambrel | W32: CompShg | X32: BrkFace | Y32: BrkFace | Z32: None | AA32: 0 | AB32: TA | AC32: Fa | AD32: BrkTil | AE32: TA | AF32: TA | AG32: No | AH32: Unf | AI32: 0 | AJ32: Unf | AK32: 0 | AL32: 649 | AM32: 649 | AN32: GasA | AO32: TA | AP32: N | AQ32: SBrkr | AR32: 649 | AS32: 668 | AT32: 0 | AU32: 1317 | AV32: 0 | AW32: 0 | AX32: 1 | AY32: 0 | AZ32: 3 | BA32: 1 | BB32: TA | BC32: 6 | BD32: Typ | BE32: 0 | BG32: Detchd | BH32: 1920 | BI32: Unf | BJ32: 1 | BK32: 250 | BL32: TA | BM32: Fa | BN32: N | BO32: 0 | BP32: 54 | BQ32: 172 | BR32: 0 | BS32: 0 | BT32: 0 | BV32: MnPrv | BX32: 0 | BY32: 7 | BZ32: 2008 | CA32: WD | CB32: Normal | CC32: 40000
A33: 32 | B33: 20 | C33: RL | E33: 8544 | F33: Pave | H33: IR1 | I33: Lvl | J33: AllPub | K33: CulDSac | L33: Gtl | M33: Sawyer | N33: Norm | O33: Norm | P33: 1Fam | Q33: 1Story | R33: 5 | S33: 6 | T33: 1966 | U33: 2006 | V33: Gable | W33: CompShg | X33: HdBoard | Y33: HdBoard | Z33: None | AA33: 0 | AB33: TA | AC33: TA | AD33: CBlock | AE33: TA | AF33: TA | AG33: No | AH33: Unf | AI33: 0 | AJ33: Unf | AK33: 0 | AL33: 1228 | AM33: 1228 | AN33: GasA | AO33: Gd | AP33: Y | AQ33: SBrkr | AR33: 1228 | AS33: 0 | AT33: 0 | AU33: 1228 | AV33: 0 | AW33: 0 | AX33: 1 | AY33: 1 | AZ33: 3 | BA33: 1 | BB33: Gd | BC33: 6 | BD33: Typ | BE33: 0 | BG33: Attchd | BH33: 1966 | BI33: Unf | BJ33: 1 | BK33: 271 | BL33: TA | BM33: TA | BN33: Y | BO33: 0 | BP33: 65 | BQ33: 0 | BR33: 0 | BS33: 0 | BT33: 0 | BV33: MnPrv | BX33: 0 | BY33: 6 | BZ33: 2008 | CA33: WD | CB33: Normal | CC33: 149350
A34: 33 | B34: 20 | C34: RL | D34: 85 | E34: 11049 | F34: Pave | H34: Reg | I34: Lvl | J34: AllPub | K34: Corner | L34: Gtl | M34: CollgCr | N34: Norm | O34: Norm | P34: 1Fam | Q34: 1Story | R34: 8 | S34: 5 | T34: 2007 | U34: 2007 | V34: Gable | W34: CompShg | X34: VinylSd | Y34: VinylSd | Z34: None | AA34: 0 | AB34: Gd | AC34: TA | AD34: PConc | AE34: Ex | AF34: TA | AG34: Av | AH34: Unf | AI34: 0 | AJ34: Unf | AK34: 0 | AL34: 1234 | AM34: 1234 | AN34: GasA | AO34: Ex | AP34: Y | AQ34: SBrkr | AR34: 1234 | AS34: 0 | AT34: 0 | AU34: 1234 | AV34: 0 | AW34: 0 | AX34: 2 | AY34: 0 | AZ34: 3 | BA34: 1 | BB34: Gd | BC34: 7 | BD34: Typ | BE34: 0 | BG34: Attchd | BH34: 2007 | BI34: RFn | BJ34: 2 | BK34: 484 | BL34: TA | BM34: TA | BN34: Y | BO34: 0 | BP34: 30 | BQ34: 0 | BR34: 0 | BS34: 0 | BT34: 0 | BX34: 0 | BY34: 1 | BZ34: 2008 | CA34: WD | CB34: Normal | CC34: 179900
A35: 34 | B35: 20 | C35: RL | D35: 70 | E35: 10552 | F35: Pave | H35: IR1 | I35: Lvl | J35: AllPub | K35: Inside | L35: Gtl | M35: mes | N35: Norm | O35: Norm | P35: 1Fam | Q35: 1Story | R35: 5 | S35: 5 | T35: 1959 | U35: 1959 | V35: Hip | W35: CompShg | X35: BrkFace | Y35: BrkFace | Z35: None | AA35: 0 | AB35: TA | AC35: TA | AD35: CBlock | AE35: TA | AF35: TA | AG35: No | AH35: Rec | AI35: 1018 | AJ35: Unf | AK35: 0 | AL35: 380 | AM35: 1398 | AN35: GasA | AO35: Gd | AP35: Y | AQ35: SBrkr | AR35: 1700 | AS35: 0 | AT35: 0 | AU35: 1700 | AV35: 0 | AW35: 1 | AX35: 1 | AY35: 1 | AZ35: 4 | BA35: 1 | BB35: Gd | BC35: 6 | BD35: Typ | BE35: 1 | BF35: Gd | BG35: Attchd | BH35: 1959 | BI35: RFn | BJ35: 2 | BK35: 447 | BL35: TA | BM35: TA | BN35: Y | BO35: 0 | BP35: 38 | BQ35: 0 | BR35: 0 | BS35: 0 | BT35: 0 | BX35: 0 | BY35: 4 | BZ35: 2010 | CA35: WD | CB35: Normal | CC35: 165500
A36: 35 | B36: 120 | C36: RL | D36: 60 | E36: 7313 | F36: Pave | H36: Reg | I36: Lvl | J36: AllPub | K36: Inside | L36: Gtl | M36: NridgHt | N36: Norm | O36: Norm | P36: TwnhsE | Q36: 1Story | R36: 9 | S36: 5 | T36: 2005 | U36: 2005 | V36: Hip | W36: CompShg | X36: MetalSd | Y36: MetalSd | Z36: BrkFace | AA36: 246 | AB36: Ex | AC36: TA | AD36: PConc | AE36: Ex | AF36: TA | AG36: No | AH36: GLQ | AI36: 1153 | AJ36: Unf | AK36: 0 | AL36: 408 | AM36: 1561 | AN36: GasA | AO36: Ex | AP36: Y | AQ36: SBrkr | AR36: 1561 | AS36: 0 | AT36: 0 | AU36: 1561 | AV36: 1 | AW36: 0 | AX36: 2 | AY36: 0 | AZ36: 2 | BA36: 1 | BB36: Ex | BC36: 6 | BD36: Typ | BE36: 1 | BF36: Gd | BG36: Attchd | BH36: 2005 | BI36: Fin | BJ36: 2 | BK36: 556 | BL36: TA | BM36: TA | BN36: Y | BO36: 203 | BP36: 47 | BQ36: 0 | BR36: 0 | BS36: 0 | BT36: 0 | BX36: 0 | BY36: 8 | BZ36: 2007 | CA36: WD | CB36: Normal | CC36: 277500
A37: 36 | B37: 60 | C37: RL | D37: 108 | E37: 13418 | F37: Pave | H37: Reg | I37: Lvl | J37: AllPub | K37: Inside | L37: Gtl | M37: NridgHt | N37: Norm | O37: Norm | P37: 1Fam | Q37: 2Story | R37: 8 | S37: 5 | T37: 2004 | U37: 2005 | V37: Gable | W37: CompShg | X37: VinylSd | Y37: VinylSd | Z37: Stone | AA37: 132 | AB37: Gd | AC37: TA | AD37: PConc | AE37: Ex | AF37: TA | AG37: Av | AH37: Unf | AI37: 0 | AJ37: Unf | AK37: 0 | AL37: 1117 | AM37: 1117 | AN37: GasA | AO37: Ex | AP37: Y | AQ37: SBrkr | AR37: 1132 | AS37: 1320 | AT37: 0 | AU37: 2452 | AV37: 0 | AW37: 0 | AX37: 3 | AY37: 1 | AZ37: 4 | BA37: 1 | BB37: Gd | BC37: 9 | BD37: Typ | BE37: 1 | BF37: Gd | BG37: BuiltIn | BH37: 2004 | BI37: Fin | BJ37: 3 | BK37: 691 | BL37: TA | BM37: TA | BN37: Y | BO37: 113 | BP37: 32 | BQ37: 0 | BR37: 0 | BS37: 0 | BT37: 0 | BX37: 0 | BY37: 9 | BZ37: 2006 | CA37: WD | CB37: Normal | CC37: 309000
A38: 37 | B38: 20 | C38: RL | D38: 112 | E38: 10859 | F38: Pave | H38: Reg | I38: Lvl | J38: AllPub | K38: Corner | L38: Gtl | M38: CollgCr | N38: Norm | O38: Norm | P38: 1Fam | Q38: 1Story | R38: 5 | S38: 5 | T38: 1994 | U38: 1995 | V38: Gable | W38: CompShg | X38: VinylSd | Y38: VinylSd | Z38: None | AA38: 0 | AB38: TA | AC38: TA | AD38: PConc | AE38: Gd | AF38: TA | AG38: No | AH38: Unf | AI38: 0 | AJ38: Unf | AK38: 0 | AL38: 1097 | AM38: 1097 | AN38: GasA | AO38: Ex | AP38: Y | AQ38: SBrkr | AR38: 1097 | AS38: 0 | AT38: 0 | AU38: 1097 | AV38: 0 | AW38: 0 | AX38: 1 | AY38: 1 | AZ38: 3 | BA38: 1 | BB38: TA | BC38: 6 | BD38: Typ | BE38: 0 | BG38: Attchd | BH38: 1995 | BI38: Unf | BJ38: 2 | BK38: 672 | BL38: TA | BM38: TA | BN38: Y | BO38: 392 | BP38: 64 | BQ38: 0 | BR38: 0 | BS38: 0 | BT38: 0 | BX38: 0 | BY38: 6 | BZ38: 2009 | CA38: WD | CB38: Normal | CC38: 145000
A39: 38 | B39: 20 | C39: RL | D39: 74 | E39: 8532 | F39: Pave | H39: Reg | I39: Lvl | J39: AllPub | K39: Inside | L39: Gtl | M39: mes | N39: Norm | O39: Norm | P39: 1Fam | Q39: 1Story | R39: 5 | S39: 6 | T39: 1954 | U39: 1990 | V39: Hip | W39: CompShg | X39: Wd Sdng | Y39: Wd Sdng | Z39: BrkFace | AA39: 650 | AB39: TA | AC39: TA | AD39: CBlock | AE39: TA | AF39: TA | AG39: No | AH39: Rec | AI39: 1213 | AJ39: Unf | AK39: 0 | AL39: 84 | AM39: 1297 | AN39: GasA | AO39: Gd | AP39: Y | AQ39: SBrkr | AR39: 1297 | AS39: 0 | AT39: 0 | AU39: 1297 | AV39: 0 | AW39: 1 | AX39: 1 | AY39: 0 | AZ39: 3 | BA39: 1 | BB39: TA | BC39: 5 | BD39: Typ | BE39: 1 | BF39: TA | BG39: Attchd | BH39: 1954 | BI39: Fin | BJ39: 2 | BK39: 498 | BL39: TA | BM39: TA | BN39: Y | BO39: 0 | BP39: 0 | BQ39: 0 | BR39: 0 | BS39: 0 | BT39: 0 | BX39: 0 | BY39: 10 | BZ39: 2009 | CA39: WD | CB39: Normal | CC39: 153000
A40: 39 | B40: 20 | C40: RL | D40: 68 | E40: 7922 | F40: Pave | H40: Reg | I40: Lvl | J40: AllPub | K40: Inside | L40: Gtl | M40: mes | N40: Norm | O40: Norm | P40: 1Fam | Q40: 1Story | R40: 5 | S40: 7 | T40: 1953 | U40: 2007 | V40: Gable | W40: CompShg | X40: VinylSd | Y40: VinylSd | Z40: None | AA40: 0 | AB40: TA | AC40: Gd | AD40: CBlock | AE40: TA | AF40: TA | AG40: No | AH40: GLQ | AI40: 731 | AJ40: Unf | AK40: 0 | AL40: 326 | AM40: 1057 | AN40: GasA | AO40: TA | AP40: Y | AQ40: SBrkr | AR40: 1057 | AS40: 0 | AT40: 0 | AU40: 1057 | AV40: 1 | AW40: 0 | AX40: 1 | AY40: 0 | AZ40: 3 | BA40: 1 | BB40: Gd | BC40: 5 | BD40: Typ | BE40: 0 | BG40: Detchd | BH40: 1953 | BI40: Unf | BJ40: 1 | BK40: 246 | BL40: TA | BM40: TA | BN40: Y | BO40: 0 | BP40: 52 | BQ40: 0 | BR40: 0 | BS40: 0 | BT40: 0 | BX40: 0 | BY40: 1 | BZ40: 2010 | CA40: WD | CB40: Abnorml | CC40: 109000
...

Sheet Analysis1
A1: Column1 | B1: Column2
A2: OverallQual | B2: =CORREL(Data!R2:R1461, Data!CC2:CC1461) -> 0.7909816
A3: GrLivArea | B3: =CORREL(Data!AU2:AU1461, Data!CC2:CC1461) -> 0.70862448
A4: TotalBsmtSF | B4: =CORREL(Data!AM2:AM1461, Data!CC2:CC1461) -> 0.61358055
A5: GarageCars | B5: =CORREL(Data!BJ2:BJ1461, Data!CC2:CC1461) -> 0.6404092
A6: GarageArea | B6: =CORREL(Data!BK2:BK1461, Data!CC2:CC1461) -> 0.62343144
A7: YearBuilt | B7: =CORREL(Data!T2:T1461, Data!CC2:CC1461) -> 0.52289733

Sheet Analysis2
B1: Count | C1: Average
A2: 1 | B2: =COUNTIF(Data!$R$2:$R$1461, A2) -> 2 | C2: =AVERAGEIF(Data!$R$2:$R$1461, A2, Data!$CC$2:$CC$1461) -> 50150
A3: 2 | B3: =COUNTIF(Data!$R$2:$R$1461, A3) -> 3 | C3: =AVERAGEIF(Data!$R$2:$R$1461, A3, Data!$CC$2:$CC$1461) -> 51770.333
A4: 3 | B4: =COUNTIF(Data!$R$2:$R$1461, A4) -> 20 | C4: =AVERAGEIF(Data!$R$2:$R$1461, A4, Data!$CC$2:$CC$1461) -> 87473.75
A5: 4 | B5: =COUNTIF(Data!$R$2:$R$1461, A5) -> 116 | C5: =AVERAGEIF(Data!$R$2:$R$1461, A5, Data!$CC$2:$CC$1461) -> 108420.66
A6: 5 | B6: =COUNTIF(Data!$R$2:$R$1461, A6) -> 397 | C6: =AVERAGEIF(Data!$R$2:$R$1461, A6, Data!$CC$2:$CC$1461) -> 133523.35
A7: 6 | B7: =COUNTIF(Data!$R$2:$R$1461, A7) -> 374 | C7: =AVERAGEIF(Data!$R$2:$R$1461, A7, Data!$CC$2:$CC$1461) -> 161603.03
A8: 7 | B8: =COUNTIF(Data!$R$2:$R$1461, A8) -> 319 | C8: =AVERAGEIF(Data!$R$2:$R$1461, A8, Data!$CC$2:$CC$1461) -> 207716.42
A9: 8 | B9: =COUNTIF(Data!$R$2:$R$1461, A9) -> 168 | C9: =AVERAGEIF(Data!$R$2:$R$1461, A9, Data!$CC$2:$CC$1461) -> 274735.54
A10: 9 | B10: =COUNTIF(Data!$R$2:$R$1461, A10) -> 43 | C10: =AVERAGEIF(Data!$R$2:$R$1461, A10, Data!$CC$2:$CC$1461) -> 367513.02
A11: 10 | B11: =COUNTIF(Data!$R$2:$R$1461, A11) -> 18 | C11: =AVERAGEIF(Data!$R$2:$R$1461, A11, Data!$CC$2:$CC$1461) -> 438588.39

Sheet Analysis3
A1: Neighborhood | B1: Average | C1: Count
A2: NoRidge | B2: =AVERAGEIF(Data!$M$2:$M$1461, A2, Data!$CC$2:$CC$1461) -> 335295.32 | C2: =COUNTIF(Data!$M$2:$M$1461, A2) -> 41
A3: NridgHt | B3: =AVERAGEIF(Data!$M$2:$M$1461, A3, Data!$CC$2:$CC$1461) -> 316270.62 | C3: =COUNTIF(Data!$M$2:$M$1461, A3) -> 77
A4: StoneBr | B4: =AVERAGEIF(Data!$M$2:$M$1461, A4, Data!$CC$2:$CC$1461) -> 310499 | C4: =COUNTIF(Data!$M$2:$M$1461, A4) -> 25
A5: Timber | B5: =AVERAGEIF(Data!$M$2:$M$1461, A5, Data!$CC$2:$CC$1461) -> 242247.45 | C5: =COUNTIF(Data!$M$2:$M$1461, A5) -> 38
A6: Veenker | B6: =AVERAGEIF(Data!$M$2:$M$1461, A6, Data!$CC$2:$CC$1461) -> 238772.73 | C6: =COUNTIF(Data!$M$2:$M$1461, A6) -> 11
A7: Somerst | B7: =AVERAGEIF(Data!$M$2:$M$1461, A7, Data!$CC$2:$CC$1461) -> 225379.84 | C7: =COUNTIF(Data!$M$2:$M$1461, A7) -> 86
A8: ClearCr | B8: =AVERAGEIF(Data!$M$2:$M$1461, A8, Data!$CC$2:$CC$1461) -> 212565.43 | C8: =COUNTIF(Data!$M$2:$M$1461, A8) -> 28
A9: Crawfor | B9: =AVERAGEIF(Data!$M$2:$M$1461, A9, Data!$CC$2:$CC$1461) -> 210624.73 | C9: =COUNTIF(Data!$M$2:$M$1461, A9) -> 51
A10: CollgCr | B10: =AVERAGEIF(Data!$M$2:$M$1461, A10, Data!$CC$2:$CC$1461) -> 197965.77 | C10: =COUNTIF(Data!$M$2:$M$1461, A10) -> 150
A11: Blmngtn | B11: =AVERAGEIF(Data!$M$2:$M$1461, A11, Data!$CC$2:$CC$1461) -> 194870.88 | C11: =COUNTIF(Data!$M$2:$M$1461, A11) -> 17
A12: Gilbert | B12: =AVERAGEIF(Data!$M$2:$M$1461, A12, Data!$CC$2:$CC$1461) -> 192854.51 | C12: =COUNTIF(Data!$M$2:$M$1461, A12) -> 79
A13: NWAmes | B13: =AVERAGEIF(Data!$M$2:$M$1461, A13, Data!$CC$2:$CC$1461) -> 189050.07 | C13: =COUNTIF(Data!$M$2:$M$1461, A13) -> 73
... A26: MeadowV | B26: =AVERAGEIF(Data!$M$2:$M$1461, A26, Data!$CC$2:$CC$1461) -> 98576.471 | C26: =COUNTIF(Data!$M$2:$M$1461, A26) -> 17

Sheet Analysis4
A1: =CORREL(Data!AU2:AU1461, Data!CC2:CC1461) -> 0.70862448 | B1: GrLivArea | C1: SalePrice
A2: =CORREL(Data!AR2:AR1461, Data!CC2:CC1461) -> 0.60585218 | B2: 1710 | C2: 208500
A3: =CORREL(Data!AS2:AS1461, Data!CC2:CC1461) -> 0.3193338 | B3: 1262 | C3: 181500
A4: =CORREL(Data!AM2:AM1461, Data!CC2:CC1461) -> 0.61358055 | B4: 1786 | C4: 223500
B5: 1717 | C5: 140000
B6: 2198 | C6: 250000
B7: 1362 | C7: 143000
B8: 1694 | C8: 307000
B9: 2090 | C9: 200000
B10: 1774 | C10: 129900
B11: 1077 | C11: 118000
B12: 1040 | C12: 129500
B13: 2324 | C13: 345000
B14: 912 | C14: 144000
B15: 1494 | C15: 279500
B16: 1253 | C16: 157000
... B1461: 1256 | C1461: 147500

Sheet Analysis5
A1: YearBuilt | B1: YearRemodAdd | C1: SalePrice
A2: 2003 | B2: 2003 | C2: 208500
A3: 1976 | B3: 1976 | C3: 181500 | E3: 1900 | F3: =AVERAGEIFS(Data!$CC$2:$CC$1461, Data!$T$2:$T$1461, ">="&E3) -> 180926
A4: 2001 | B4: 2002 | C4: 223500 | E4: 1950 | F4: =AVERAGEIFS(Data!$CC$2:$CC$1461, Data!$T$2:$T$1461, ">="&E4) -> 194468.81
A5: 1915 | B5: 1970 | C5: 140000 | E5: 1980 | F5: =AVERAGEIFS(Data!$CC$2:$CC$1461, Data!$T$2:$T$1461, ">="&E5) -> 233482.33
A6: 2000 | B6: 2000 | C6: 250000 | E6: 2000 | F6: =AVERAGEIFS(Data!$CC$2:$CC$1461, Data!$T$2:$T$1461, ">="&E6) -> 242439.16
A7: 1993 | B7: 1995 | C7: 143000
A8: 2004 | B8: 2005 | C8: 307000
A9: 1973 | B9: 1973 | C9: 200000
A10: 1931 | B10: 1950 | C10: 129900
A11: 1939 | B11: 1950 | C11: 118000
A12: 1965 | B12: 1965 | C12: 129500
A13: 2005 | B13: 2006 | C13: 345000
A14: 1962 | B14: 1962 | C14: 144000
A15: 2006 | B15: 2007 | C15: 279500
A16: 1960 | B16: 1960 | C16: 157000
A17: 1929 | B17: 2001 | C17: 132000
A18: 1970 | B18: 1970 | C18: 149000
... A1461: 1965 | B1461: 1965 | C1461: 147500

Sheet Analysis6
B1: Count | C1: Average | D1: Correl=
A2: 0 | B2: =COUNTIF(Data!$BJ$2:$BJ$1461, A2) -> 81 | C2: =AVERAGEIF(Data!$BJ$2:$BJ$1461, A2, Data!$CC$2:$CC$1461) -> 103317.28 | D2: =CORREL(Data!BK2:BK1461, Data!CC2:CC1461) -> 0.62343144
A3: 1 | B3: =COUNTIF(Data!$BJ$2:$BJ$1461, A3) -> 369 | C3: =AVERAGEIF(Data!$BJ$2:$BJ$1461, A3, Data!$CC$2:$CC$1461) -> 128116.69 | D3: =CORREL(Data!BK3:BK1462, Data!CC3:CC1462) -> 0.62339998
A4: 2 | B4: =COUNTIF(Data!$BJ$2:$BJ$1461, A4) -> 824 | C4: =AVERAGEIF(Data!$BJ$2:$BJ$1461, A4, Data!$CC$2:$CC$1461) -> 183851.66 | D4: =CORREL(Data!BK4:BK1463, Data!CC4:CC1463) -> 0.62340108
A5: 3 | B5: =COUNTIF(Data!$BJ$2:$BJ$1461, A5) -> 181 | C5: =AVERAGEIF(Data!$BJ$2:$BJ$1461, A5, Data!$CC$2:$CC$1461) -> 309636.12 | D5: =CORREL(Data!BK5:BK1464, Data!CC5:CC1464) -> 0.62331551
A6: 4 | B6: =COUNTIF(Data!$BJ$2:$BJ$1461, A6) -> 5 | C6: =AVERAGEIF(Data!$BJ$2:$BJ$1461, A6, Data!$CC$2:$CC$1461) -> 192655.8 | D6: =CORREL(Data!BK6:BK1465, Data!CC6:CC1465) -> 0.62378538

Sheet Analysis7
A1: Bedroom
B2: Count | C2: Average | D2: Correl
A3: 0 | B3: =COUNTIF(Data!$AZ$2:$AZ$1461, A2) -> 6 | C3: =AVERAGEIF(Data!$AZ$2:$AZ$1461, A3, Data!$CC$2:$CC$1461) -> 221493.17 | D3: =CORREL(Data!AZ2:AZ1461, Data!CC2:CC1461) -> 0.16821315
A4: 1 | B4: =COUNTIF(Data!$AZ$2:$AZ$1461, A3) -> 6 | C4: =AVERAGEIF(Data!$AZ$2:$AZ$1461, A4, Data!$CC$2:$CC$1461) -> 173162.42 | D4: =CORREL(Data!AZ3:AZ1462, Data!CC3:CC1462) -> 0.16818267
A5: 2 | B5: =COUNTIF(Data!$AZ$2:$AZ$1461, A4) -> 50 | C5: =AVERAGEIF(Data!$AZ$2:$AZ$1461, A5, Data!$CC$2:$CC$1461) -> 158197.66 | D5: =CORREL(Data!AZ4:AZ1463, Data!CC4:CC1463) -> 0.16818337
A6: 3 | B6: =COUNTIF(Data!$AZ$2:$AZ$1461, A5) -> 358 | C6: =AVERAGEIF(Data!$AZ$2:$AZ$1461, A6, Data!$CC$2:$CC$1461) -> 181056.87 | D6: =CORREL(Data!AZ5:AZ1464, Data!CC5:CC1464) -> 0.16814121
A7: 4 | B7: =COUNTIF(Data!$AZ$2:$AZ$1461, A6) -> 804 | C7: =AVERAGEIF(Data!$AZ$2:$AZ$1461, A7, Data!$CC$2:$CC$1461) -> 220421.25 | D7: =CORREL(Data!AZ6:AZ1465, Data!CC6:CC1465) -> 0.16821594
A8: 5 | B8: =COUNTIF(Data!$AZ$2:$AZ$1461, A7) -> 213 | C8: =AVERAGEIF(Data!$AZ$2:$AZ$1461, A8, Data!$CC$2:$CC$1461) -> 180819.05 | D8: =CORREL(Data!AZ7:AZ1466, Data!CC7:CC1466) -> 0.167541
A17: Bathroom
B18: Count | C18: Average | D18: Correl
A19: 0 | B19: =COUNTIF(Data!$AX$2:$AX$1461, A2) -> 9 | C19: =AVERAGEIF(Data!$AX$2:$AX$1461, A2, Data!$CC$2:$CC$1461) -> 165200.89 | D19: =CORREL(Data!AX2:AX1461, Data!CC2:CC1461) -> 0.56066376
A20: 1 | B20: =COUNTIF(Data!$AX$2:$AX$1461, A3) -> 9 | C20: =AVERAGEIF(Data!$AX$2:$AX$1461, A3, Data!$CC$2:$CC$1461) -> 165200.89 | D20: =CORREL(Data!AX3:AX1462, Data!CC3:CC1462) -> 0.56061879
A21: 2 | B21: =COUNTIF(Data!$AX$2:$AX$1461, A4) -> 650 | C21: =AVERAGEIF(Data!$AX$2:$AX$1461, A4, Data!$CC$2:$CC$1461) -> 134751.44 | D21: =CORREL(Data!AX4:AX1463, Data!CC4:CC1463) -> 0.5607348
A22: 3 | B22: =COUNTIF(Data!$AX$2:$AX$1461, A5) -> 768 | C22: =AVERAGEIF(Data!$AX$2:$AX$1461, A5, Data!$CC$2:$CC$1461) -> 213009.83 | D22: =CORREL(Data!AX5:AX1464, Data!CC5:CC1464) -> 0.56061947
A23: 4 | B23: =COUNTIF(Data!$AX$2:$AX$1461, A6) -> 33 | C23: =AVERAGEIF(Data!$AX$2:$AX$1461, A6, Data!$CC$2:$CC$1461) -> 347822.91 | D23: =CORREL(Data!AX6:AX1465, Data!CC6:CC1465) -> 0.56051057
A24: 5 | B24: =COUNTIF(Data!$AX$2:$AX$1461, A7) -> 0 | C24: =AVERAGEIF(Data!$AX$2:$AX$1461, A7, Data!$CC$2:$CC$1461) -> #DIV/0! | D24: =CORREL(Data!AX7:AX1466, Data!CC7:CC1466) -> 0.56030418
A29: Fireplace
B30: Count | C30: Average | D30: Correl
A31: 0 | B31: =COUNTIF(Data!$BE$2:$BE$1461, A7) -> 0 | C31: =AVERAGEIF(Data!$BE$2:$BE$1461, A5, Data!$CC$2:$CC$1461) -> 240588.54
A32: 1 | B32: =COUNTIF(Data!$BE$2:$BE$1461, A8) -> 0 | C32: =AVERAGEIF(Data!$BE$2:$BE$1461, A6, Data!$CC$2:$CC$1461) -> 252000
A33: 2 | B33: =COUNTIF(Data!$BE$2:$BE$1461, A9) -> 690 | C33: =AVERAGEIF(Data!$BE$2:$BE$1461, A7, Data!$CC$2:$CC$1461) -> #DIV/0!
A34: 3 | B34: =COUNTIF(Data!$BE$2:$BE$1461, A10) -> 690 | C34: =AVERAGEIF(Data!$BE$2:$BE$1461, A8, Data!$CC$2:$CC$1461) -> #DIV/0!
A35: 4 | B35: =COUNTIF(Data!$BE$2:$BE$1461, A11) -> 690 | C35: =AVERAGEIF(Data!$BE$2:$BE$1461, A9, Data!$CC$2:$CC$1461) -> 141331.48
A36: 5 | B36: =COUNTIF(Data!$BE$2:$BE$1461, A12) -> 690 | C36: =AVERAGEIF(Data!$BE$2:$BE$1461, A10, Data!$CC$2:$CC$1461) -> 141331.48

Sheet Analysis8
A1: HouseStyle | B1: Count | D1: BldgType | E1: Count | G1: Foundation | H1: Count | J1: RoofStyle | K1: Count | M1: Heating | N1: Count
A2: 2Story | B2: =COUNTIF(Data!$Q$2:$Q$1461, A2) -> 445 | D2: 1Fam | E2: =COUNTIF(Data!$P$2:$P$1461, D2) -> 1220 | G2: PConc | H2: =COUNTIF(Data!$AD$2:$AD$1461, G2) -> 647 | J2: Gable | K2: =COUNTIF(Data!$V$2:$V$1461, J2) -> 1141 | M2: GasA | N2: =COUNTIF(Data!$AN$2:$AN$1461, M2) -> 1428
A3: 1Story | B3: =COUNTIF(Data!$Q$2:$Q$1461, A3) -> 726 | D3: 2fmCon | E3: =COUNTIF(Data!$P$2:$P$1461, D3) -> 31 | G3: CBlock | H3: =COUNTIF(Data!$AD$2:$AD$1461, G3) -> 634 | J3: Hip | K3: =COUNTIF(Data!$V$2:$V$1461, J3) -> 286 | M3: GasW | N3: =COUNTIF(Data!$AN$2:$AN$1461, M3) -> 18
A4: 1.5Fin | B4: =COUNTIF(Data!$Q$2:$Q$1461, A4) -> 154 | D4: Duplex | E4: =COUNTIF(Data!$P$2:$P$1461, D4) -> 52 | G4: BrkTil | H4: =COUNTIF(Data!$AD$2:$AD$1461, G4) -> 146 | J4: Gambrel | K4: =COUNTIF(Data!$V$2:$V$1461, J4) -> 11 | M4: Grav | N4: =COUNTIF(Data!$AN$2:$AN$1461, M4) -> 7
A5: 1.5Unf | B5: =COUNTIF(Data!$Q$2:$Q$1461, A5) -> 14 | D5: TwnhsE | E5: =COUNTIF(Data!$P$2:$P$1461, D5) -> 114 | G5: Wood | H5: =COUNTIF(Data!$AD$2:$AD$1461, G5) -> 3 | J5: Mansard | K5: =COUNTIF(Data!$V$2:$V$1461, J5) -> 7 | M5: Wall | N5: =COUNTIF(Data!$AN$2:$AN$1461, M5) -> 4
A6: SFoyer | B6: =COUNTIF(Data!$Q$2:$Q$1461, A6) -> 37 | D6: Twnhs | E6: =COUNTIF(Data!$P$2:$P$1461, D6) -> 43 | G6: Slab | H6: =COUNTIF(Data!$AD$2:$AD$1461, G6) -> 24 | J6: Flat | K6: =COUNTIF(Data!$V$2:$V$1461, J6) -> 13 | M6: OthW | N6: =COUNTIF(Data!$AN$2:$AN$1461, M6) -> 2
A7: SLvl | B7: =COUNTIF(Data!$Q$2:$Q$1461, A7) -> 65 | G7: Stone | H7: =COUNTIF(Data!$AD$2:$AD$1461, G7) -> 6 | J7: Shed | K7: =COUNTIF(Data!$V$2:$V$1461, J7) -> 2 | M7: Floor | N7: =COUNTIF(Data!$AN$2:$AN$1461, M7) -> 1
A8: 2.5Unf | B8: =COUNTIF(Data!$Q$2:$Q$1461, A8) -> 11
A9: 2.5Fin | B9: =COUNTIF(Data!$Q$2:$Q$1461, A9) -> 8

Sheet Analysis9
A1: Highest Price | B1: Lowest Price | E1: Q1 | F1: =_xlfn.QUARTILE.INC(Data!CC2:CC1461, 1) -> 129975
A2: =LARGE(Data!$CC$2:$CC$1461, 1) -> 755000 | B2: =SMALL(Data!$CC$2:$CC$1461, 1) -> 34900 | E2: Q3 | F2: =_xlfn.QUARTILE.INC(Data!CC2:CC1461, 3) -> 214000
A3: =LARGE(Data!$CC$2:$CC$1461, 2) -> 745000 | B3: =SMALL(Data!$CC$2:$CC$1461, 2) -> 35311 | E3: Upper limit | F3: =F2+ 1.5*(F2-F1) -> 340037.5
A4: =LARGE(Data!$CC$2:$CC$1461, 3) -> 625000 | B4: =SMALL(Data!$CC$2:$CC$1461, 3) -> 37900
A5: =LARGE(Data!$CC$2:$CC$1461, 4) -> 611657 | B5: =SMALL(Data!$CC$2:$CC$1461, 4) -> 39300
A6: =LARGE(Data!$CC$2:$CC$1461, 5) -> 582933 | B6: =SMALL(Data!$CC$2:$CC$1461, 5) -> 40000

Sheet Analysis10
A1: Year | B1: Count | C1: Average
A2: 2006 | B2: =COUNTIF(Data!$BZ$2:$BZ$1461, A2) -> 314 | C2: =AVERAGEIF(Data!$BZ$2:$BZ$1461, A2, Data!$CC$2:$CC$1461) -> 182549.46
A3: 2007 | B3: =COUNTIF(Data!$BZ$2:$BZ$1461, A3) -> 329 | C3: =AVERAGEIF(Data!$BZ$2:$BZ$1461, A3, Data!$CC$2:$CC$1461) -> 186063.15
A4: 2008 | B4: =COUNTIF(Data!$BZ$2:$BZ$1461, A4) -> 304 | C4: =AVERAGEIF(Data!$BZ$2:$BZ$1461, A4, Data!$CC$2:$CC$1461) -> 177360.84
A5: 2009 | B5: =COUNTIF(Data!$BZ$2:$BZ$1461, A5) -> 338 | C5: =AVERAGEIF(Data!$BZ$2:$BZ$1461, A5, Data!$CC$2:$CC$1461) -> 179432.1
A6: 2010 | B6: =COUNTIF(Data!$BZ$2:$BZ$1461, A6) -> 175 | C6: =AVERAGEIF(Data!$BZ$2:$BZ$1461, A6, Data!$CC$2:$CC$1461) -> 177393.67

Sheet Analysis11
A1: Empty Entries
A2: PoolQC | B2: =COUNTBLANK(Data!BU2:BU1461) -> 1453 | C2: =B2/1460 -> 0.99520548
A3: MiscFeature | B3: =COUNTBLANK(Data!BW2:BW1461) -> 1406 | C3: =B3/1460 -> 0.9630137
A4: Alley | B4: =COUNTBLANK(Data!G2:G1461) -> 1369 | C4: =B4/1460 -> 0.93767123
A5: Fence | B5: =COUNTBLANK(Data!BV2:BV1461) -> 1179 | C5: =B5/1460 -> 0.80753425
A6: FireplaceQu | B6: =COUNTBLANK(Data!BF2:BF1461) -> 690 | C6: =B6/1460 -> 0.47260274
A7: LotFrontage | B7: =COUNTBLANK(Data!D2:D1461) -> 259 | C7: =B7/1460 -> 0.17739726
A8: GarageType | B8: =COUNTBLANK(Data!BG2:BG1461) -> 81 | C8: =B8/1460 -> 0.055479452
A9: GarageYrBlt | B9: =COUNTBLANK(Data!BH2:BH1461) -> 81 | C9: =B9/1460 -> 0.055479452
A10: GarageFinish | B10: =COUNTBLANK(Data!BI2:BI1461) -> 81 | C10: =B10/1460 -> 0.055479452
A11: GarageQual | B11: =COUNTBLANK(Data!BL2:BL1461) -> 81 | C11: =B11/1460 -> 0.055479452
A12: GarageCond | B12: =COUNTBLANK(Data!BM2:BM1461) -> 81 | C12: =B12/1460 -> 0.055479452
A13: BsmtExposure | B13: =COUNTBLANK(Data!AG2:AG1461) -> 38 | C13: =B13/1460 -> 0.026027397
A14: BsmtFinType2 | B14: =COUNTBLANK(Data!AJ2:AJ1461) -> 38 | C14: =B14/1460 -> 0.026027397
A15: BsmtQual | B15: =COUNTBLANK(Data!AE2:AE1461) -> 37 | C15: =B15/1460 -> 0.025342466
A16: BsmtCond | B16: =COUNTBLANK(Data!AF2:AF1461) -> 37 | C16: =B16/1460 -> 0.025342466
A17: BsmtFinType1 | B17: =COUNTBLANK(Data!AH2:AH1461) -> 37 | C17: =B17/1460 -> 0.025342466
A18: MasVnrType | B18: =COUNTBLANK(Data!Z2:Z1461) -> 8 | C18: =B18/1460 -> 0.0054794521
A19: MasVnrArea | B19: =COUNTBLANK(Data!AA2:AA1461) -> 8 | C19: =B19/1460 -> 0.0054794521
A20: TotalBsmtSF | B20: =COUNTBLANK(Data!AM2:AM1467) -> 6 | C20: =B20/1460 -> 0.004109589
A21: Electrical | B21: =COUNTBLANK(Data!AQ2:AQ1461) -> 1 | C21: =B21/1460 -> 0.00068493151
A22: Id | B22: =COUNTBLANK(Data!A2:A1461) -> 0 | C22: =B22/1460 -> 0
A23: MSSubClass | B23: =COUNTBLANK(Data!B2:B1461) -> 0 | C23: =B23/1460 -> 0
A24: MSZoning | B24: =COUNTBLANK(Data!C2:C1461) -> 0 | C24: =B24/1460 -> 0
A25: LotArea | B25: =COUNTBLANK(Data!E2:E1461) -> 0 | C25: =B25/1460 -> 0
A26: Street | B26: =COUNTBLANK(Data!F2:F1461) -> 0 | C26: =B26/1460 -> 0
A27: LotShape | B27: =COUNTBLANK(Data!H2:H1461) -> 0 | C27: =B27/1460 -> 0
A28: LandContour | B28: =COUNTBLANK(Data!I2:I1461) -> 0 | C28: =B28/1460 -> 0
A29: Utilities | B29: =COUNTBLANK(Data!J2:J1461) -> 0 | C29: =B29/1460 -> 0
A30: LotConfig | B30: =COUNTBLANK(Data!K2:K1461) -> 0 | C30: =B30/1460 -> 0
A31: LandSlope | B31: =COUNTBLANK(Data!L2:L1461) -> 0 | C31: =B31/1460 -> 0
A32: Neighborhood | B32: =COUNTBLANK(Data!M2:M1461) -> 0 | C32: =B32/1460 -> 0
A33: Condition1 | B33: =COUNTBLANK(Data!N2:N1461) -> 0 | C33: =B33/1460 -> 0
A34: Condition2 | B34: =COUNTBLANK(Data!O2:O1461) -> 0 | C34: =B34/1460 -> 0
A35: BldgType | B35: =COUNTBLANK(Data!P2:P1461) -> 0 | C35: =B35/1460 -> 0
A36: HouseStyle | B36: =COUNTBLANK(Data!Q2:Q1461) -> 0 | C36: =B36/1460 -> 0
A37: OverallQual | B37: =COUNTBLANK(Data!R2:R1461) -> 0 | C37: =B37/1460 -> 0
A38: OverallCond | B38: =COUNTBLANK(Data!S2:S1461) -> 0 | C38: =B38/1460 -> 0
A39: YearBuilt | B39: =COUNTBLANK(Data!T2:T1461) -> 0 | C39: =B39/1460 -> 0
A40: YearRemodAdd | B40: =COUNTBLANK(Data!U2:U1461) -> 0 | C40: =B40/1460 -> 0
...

Sheet Analysis12
A1: SalePrice
A2: 755000 | C2: From the Analysis 1, Overall Quality and GrLivArea can help in prediction.
A3: 745000
A4: 625000
A5: 611657
A6: 582933
A7: 556581
A8: 555000
A9: 538000
A10: 501837
A11: 485000
A12: 475000
A13: 466500
A14: 465000
... A1461: 34900
